<?xml version="1.0" ?>
<!-- =================================================================================== -->
<!-- |    This document was autogenerated by xacro from low-cost-arm.xacro             | -->
<!-- |    EDITING THIS FILE BY HAND IS NOT RECOMMENDED                                 | -->
<!-- =================================================================================== -->
<robot name="low-cost-arm">
  <material name="silver">
    <color rgba="0.700 0.700 0.700 1.000"/>
  </material>
  <transmission name="Revolute 2_tran">
    <type>transmission_interface/SimpleTransmission</type>
    <joint name="Revolute 2">
      <hardwareInterface>hardware_interface/EffortJointInterface</hardwareInterface>
    </joint>
    <actuator name="Revolute 2_actr">
      <hardwareInterface>hardware_interface/EffortJointInterface</hardwareInterface>
      <mechanicalReduction>1</mechanicalReduction>
    </actuator>
  </transmission>
  <transmission name="Revolute 3_tran">
    <type>transmission_interface/SimpleTransmission</type>
    <joint name="Revolute 3">
      <hardwareInterface>hardware_interface/EffortJointInterface</hardwareInterface>
    </joint>
    <actuator name="Revolute 3_actr">
      <hardwareInterface>hardware_interface/EffortJointInterface</hardwareInterface>
      <mechanicalReduction>1</mechanicalReduction>
    </actuator>
  </transmission>
  <transmission name="Revolute 5_tran">
    <type>transmission_interface/SimpleTransmission</type>
    <joint name="Revolute 5">
      <hardwareInterface>hardware_interface/EffortJointInterface</hardwareInterface>
    </joint>
    <actuator name="Revolute 5_actr">
      <hardwareInterface>hardware_interface/EffortJointInterface</hardwareInterface>
      <mechanicalReduction>1</mechanicalReduction>
    </actuator>
  </transmission>
  <transmission name="Revolute 6_tran">
    <type>transmission_interface/SimpleTransmission</type>
    <joint name="Revolute 6">
      <hardwareInterface>hardware_interface/EffortJointInterface</hardwareInterface>
    </joint>
    <actuator name="Revolute 6_actr">
      <hardwareInterface>hardware_interface/EffortJointInterface</hardwareInterface>
      <mechanicalReduction>1</mechanicalReduction>
    </actuator>
  </transmission>
  <transmission name="Revolute 7_tran">
    <type>transmission_interface/SimpleTransmission</type>
    <joint name="Revolute 7">
      <hardwareInterface>hardware_interface/EffortJointInterface</hardwareInterface>
    </joint>
    <actuator name="Revolute 7_actr">
      <hardwareInterface>hardware_interface/EffortJointInterface</hardwareInterface>
      <mechanicalReduction>1</mechanicalReduction>
    </actuator>
  </transmission>
  <gazebo>
    <plugin filename="libgazebo_ros_control.so" name="control"/>
  </gazebo>
  <gazebo reference="base_link">
    <material>Gazebo/Silver</material>
    <mu1>0.2</mu1>
    <mu2>0.2</mu2>
    <selfCollide>true</selfCollide>
    <gravity>true</gravity>
  </gazebo>
  <gazebo reference="first-bracket-motor_1">
    <material>Gazebo/Silver</material>
    <mu1>0.2</mu1>
    <mu2>0.2</mu2>
    <selfCollide>true</selfCollide>
  </gazebo>
  <gazebo reference="shoulder-to-elbow-motor_v1_1">
    <material>Gazebo/Silver</material>
    <mu1>0.2</mu1>
    <mu2>0.2</mu2>
    <selfCollide>true</selfCollide>
  </gazebo>
  <gazebo reference="elbow-to-wrist-motor-reference_v1_1">
    <material>Gazebo/Silver</material>
    <mu1>0.2</mu1>
    <mu2>0.2</mu2>
    <selfCollide>true</selfCollide>
  </gazebo>
  <gazebo reference="gripper-static-motor_v2_1">
    <material>Gazebo/Silver</material>
    <mu1>0.2</mu1>
    <mu2>0.2</mu2>
    <selfCollide>true</selfCollide>
  </gazebo>
  <gazebo reference="gripper-moving-part-dumb_v2_1">
    <material>Gazebo/Silver</material>
    <mu1>0.2</mu1>
    <mu2>0.2</mu2>
    <selfCollide>true</selfCollide>
  </gazebo>
  <link name="base_link">
    <inertial>
      <origin rpy="0 0 0" xyz="-1.6196165020213455e-05 0.04676572591178276 0.014449624355634582"/>
      <mass value="0.06752363433035656"/>
      <inertia ixx="4e-05" ixy="-0.0" ixz="-0.0" iyy="3.8e-05" iyz="-9e-06" izz="5.9e-05"/>
    </inertial>
    <visual>
      <origin rpy="0 0 0" xyz="0 0 0"/>
      <geometry>
        <mesh filename="package://low-cost-arm_description/meshes/base_link.stl" scale="0.001 0.001 0.001"/>
      </geometry>
      <material name="silver"/>
    </visual>
    <collision>
      <origin rpy="0 0 0" xyz="0 0 0"/>
      <geometry>
        <mesh filename="package://low-cost-arm_description/meshes/base_link.stl" scale="0.001 0.001 0.001"/>
      </geometry>
    </collision>
  </link>
  <link name="first-bracket-motor_1">
    <inertial>
      <origin rpy="0 0 0" xyz="0.0011215335520915035 -0.011960095984038348 0.012424221873872536"/>
      <mass value="0.050669759178187244"/>
      <inertia ixx="1.4e-05" ixy="-0.0" ixz="-0.0" iyy="9e-06" iyz="-0.0" izz="1.5e-05"/>
    </inertial>
    <visual>
      <origin rpy="0 0 0" xyz="-0.00025 -0.06875 -0.0409"/>
      <geometry>
        <mesh filename="package://low-cost-arm_description/meshes/first-bracket-motor_1.stl" scale="0.001 0.001 0.001"/>
      </geometry>
      <material name="silver"/>
    </visual>
    <collision>
      <origin rpy="0 0 0" xyz="-0.00025 -0.06875 -0.0409"/>
      <geometry>
        <mesh filename="package://low-cost-arm_description/meshes/first-bracket-motor_1.stl" scale="0.001 0.001 0.001"/>
      </geometry>
    </collision>
  </link>
  <link name="shoulder-to-elbow-motor_v1_1">
    <inertial>
      <origin rpy="0 0 0" xyz="-0.0191542760740305 -0.0012683813577475112 0.07144141167892787"/>
      <mass value="0.05261369068977079"/>
      <inertia ixx="7e-05" ixy="0.0" ixz="0.0" iyy="7.2e-05" iyz="-5e-06" izz="1.1e-05"/>
    </inertial>
    <visual>
      <origin rpy="0 0 0" xyz="-0.01945 -0.06895 -0.05515"/>
      <geometry>
        <mesh filename="package://low-cost-arm_description/meshes/shoulder-to-elbow-motor_v1_1.stl" scale="0.001 0.001 0.001"/>
      </geometry>
      <material name="silver"/>
    </visual>
    <collision>
      <origin rpy="0 0 0" xyz="-0.01945 -0.06895 -0.05515"/>
      <geometry>
        <mesh filename="package://low-cost-arm_description/meshes/shoulder-to-elbow-motor_v1_1.stl" scale="0.001 0.001 0.001"/>
      </geometry>
    </collision>
  </link>
  <link name="elbow-to-wrist-motor-reference_v1_1">
    <inertial>
      <origin rpy="0 0 0" xyz="0.01951468809363352 0.026076660011439212 2.3261768583027198e-05"/>
      <mass value="0.02059907441055582"/>
      <inertia ixx="3e-06" ixy="-0.0" ixz="0.0" iyy="3e-06" iyz="-0.0" izz="5e-06"/>
    </inertial>
    <visual>
      <origin rpy="0 0 0" xyz="0.0143 -0.08375 -0.16345"/>
      <geometry>
        <mesh filename="package://low-cost-arm_description/meshes/elbow-to-wrist-motor-reference_v1_1.stl" scale="0.001 0.001 0.001"/>
      </geometry>
      <material name="silver"/>
    </visual>
    <collision>
      <origin rpy="0 0 0" xyz="0.0143 -0.08375 -0.16345"/>
      <geometry>
        <mesh filename="package://low-cost-arm_description/meshes/elbow-to-wrist-motor-reference_v1_1.stl" scale="0.001 0.001 0.001"/>
      </geometry>
    </collision>
  </link>
  <link name="gripper-static-motor_v2_1">
    <inertial>
      <origin rpy="0 0 0" xyz="0.005421565533833407 0.019034667992307075 0.00011281388318701291"/>
      <mass value="0.030801959916802346"/>
      <inertia ixx="9e-06" ixy="-2e-06" ixz="-0.0" iyy="6e-06" iyz="-0.0" izz="1.1e-05"/>
    </inertial>
    <visual>
      <origin rpy="0 0 0" xyz="0.000893 -0.128688 -0.163437"/>
      <geometry>
        <mesh filename="package://low-cost-arm_description/meshes/gripper-static-motor_v2_1.stl" scale="0.001 0.001 0.001"/>
      </geometry>
      <material name="silver"/>
    </visual>
    <collision>
      <origin rpy="0 0 0" xyz="0.000893 -0.128688 -0.163437"/>
      <geometry>
        <mesh filename="package://low-cost-arm_description/meshes/gripper-static-motor_v2_1.stl" scale="0.001 0.001 0.001"/>
      </geometry>
    </collision>
  </link>
  <link name="gripper-moving-part-dumb_v2_1">
    <inertial>
      <origin rpy="0 0 0" xyz="0.001094897934895013 0.025115003984107043 -0.01445125352746443"/>
      <mass value="0.013583445641331692"/>
      <inertia ixx="4e-06" ixy="-0.0" ixz="-0.0" iyy="2e-06" iyz="-0.0" izz="3e-06"/>
    </inertial>
    <visual>
      <origin rpy="0 0 0" xyz="0.008443 -0.141678 -0.177687"/>
      <geometry>
        <mesh filename="package://low-cost-arm_description/meshes/gripper-moving-part-dumb_v2_1.stl" scale="0.001 0.001 0.001"/>
      </geometry>
      <material name="silver"/>
    </visual>
    <collision>
      <origin rpy="0 0 0" xyz="0.008443 -0.141678 -0.177687"/>
      <geometry>
        <mesh filename="package://low-cost-arm_description/meshes/gripper-moving-part-dumb_v2_1.stl" scale="0.001 0.001 0.001"/>
      </geometry>
    </collision>
  </link>
  <joint name="Revolute 2" type="continuous">
    <origin rpy="0 0 0" xyz="0.00025 0.06875 0.0409"/>
    <parent link="base_link"/>
    <child link="first-bracket-motor_1"/>
    <axis xyz="0.0 0.0 1.0"/>
  </joint>
  <joint name="Revolute 3" type="continuous">
    <origin rpy="0 0 0" xyz="0.0192 0.0002 0.01425"/>
    <parent link="first-bracket-motor_1"/>
    <child link="shoulder-to-elbow-motor_v1_1"/>
    <axis xyz="1.0 0.0 0.0"/>
  </joint>
  <joint name="Revolute 5" type="continuous">
    <origin rpy="0 0 0" xyz="-0.03375 0.0148 0.1083"/>
    <parent link="shoulder-to-elbow-motor_v1_1"/>
    <child link="elbow-to-wrist-motor-reference_v1_1"/>
    <axis xyz="1.0 -0.0 0.0"/>
  </joint>
  <joint name="Revolute 6" type="continuous">
    <origin rpy="0 0 0" xyz="0.013407 0.044938 -1.3e-05"/>
    <parent link="elbow-to-wrist-motor-reference_v1_1"/>
    <child link="gripper-static-motor_v2_1"/>
    <axis xyz="-0.0 -1.0 0.0"/>
  </joint>
  <joint name="Revolute 7" type="continuous">
    <origin rpy="0 0 0" xyz="-0.00755 0.01299 0.01425"/>
    <parent link="gripper-static-motor_v2_1"/>
    <child link="gripper-moving-part-dumb_v2_1"/>
    <axis xyz="-0.0 -0.0 -1.0"/>
  </joint>
</robot>
