<?xml version="1.0" ?>
<!-- =================================================================================== -->
<!-- |    This document was autogenerated by xacro from low_cost_robot.xacro           | -->
<!-- |    EDITING THIS FILE BY HAND IS NOT RECOMMENDED                                 | -->
<!-- =================================================================================== -->
<robot name="low_cost_robot">
  <material name="silver">
    <color rgba="0.700 0.700 0.700 1.000"/>
  </material>
  <transmission name="joint1_tran">
    <type>transmission_interface/SimpleTransmission</type>
    <joint name="joint1">
      <hardwareInterface>hardware_interface/EffortJointInterface</hardwareInterface>
    </joint>
    <actuator name="joint1_actr">
      <hardwareInterface>hardware_interface/EffortJointInterface</hardwareInterface>
      <mechanicalReduction>1</mechanicalReduction>
    </actuator>
  </transmission>
  <transmission name="joint2_tran">
    <type>transmission_interface/SimpleTransmission</type>
    <joint name="joint2">
      <hardwareInterface>hardware_interface/EffortJointInterface</hardwareInterface>
    </joint>
    <actuator name="joint2_actr">
      <hardwareInterface>hardware_interface/EffortJointInterface</hardwareInterface>
      <mechanicalReduction>1</mechanicalReduction>
    </actuator>
  </transmission>
  <transmission name="joint3_tran">
    <type>transmission_interface/SimpleTransmission</type>
    <joint name="joint3">
      <hardwareInterface>hardware_interface/EffortJointInterface</hardwareInterface>
    </joint>
    <actuator name="joint3_actr">
      <hardwareInterface>hardware_interface/EffortJointInterface</hardwareInterface>
      <mechanicalReduction>1</mechanicalReduction>
    </actuator>
  </transmission>
  <transmission name="joint4_tran">
    <type>transmission_interface/SimpleTransmission</type>
    <joint name="joint4">
      <hardwareInterface>hardware_interface/EffortJointInterface</hardwareInterface>
    </joint>
    <actuator name="joint4_actr">
      <hardwareInterface>hardware_interface/EffortJointInterface</hardwareInterface>
      <mechanicalReduction>1</mechanicalReduction>
    </actuator>
  </transmission>
  <transmission name="joint5_tran">
    <type>transmission_interface/SimpleTransmission</type>
    <joint name="joint5">
      <hardwareInterface>hardware_interface/EffortJointInterface</hardwareInterface>
    </joint>
    <actuator name="joint5_actr">
      <hardwareInterface>hardware_interface/EffortJointInterface</hardwareInterface>
      <mechanicalReduction>1</mechanicalReduction>
    </actuator>
  </transmission>
  <transmission name="joint_gripper_tran">
    <type>transmission_interface/SimpleTransmission</type>
    <joint name="joint_gripper">
      <hardwareInterface>hardware_interface/EffortJointInterface</hardwareInterface>
    </joint>
    <actuator name="joint_gripper_actr">
      <hardwareInterface>hardware_interface/EffortJointInterface</hardwareInterface>
      <mechanicalReduction>1</mechanicalReduction>
    </actuator>
  </transmission>
  <gazebo>
    <plugin filename="libgazebo_ros_control.so" name="control"/>
  </gazebo>
  <gazebo reference="base_link">
    <material>Gazebo/Silver</material>
    <mu1>0.2</mu1>
    <mu2>0.2</mu2>
    <self_collide>true</self_collide>
    <gravity>true</gravity>
  </gazebo>
  <gazebo reference="link1_1">
    <material>Gazebo/Silver</material>
    <mu1>0.2</mu1>
    <mu2>0.2</mu2>
    <self_collide>true</self_collide>
  </gazebo>
  <gazebo reference="link2_1">
    <material>Gazebo/Silver</material>
    <mu1>0.2</mu1>
    <mu2>0.2</mu2>
    <self_collide>true</self_collide>
  </gazebo>
  <gazebo reference="link3_1">
    <material>Gazebo/Silver</material>
    <mu1>0.2</mu1>
    <mu2>0.2</mu2>
    <self_collide>true</self_collide>
  </gazebo>
  <gazebo reference="link4_1">
    <material>Gazebo/Silver</material>
    <mu1>0.2</mu1>
    <mu2>0.2</mu2>
    <self_collide>true</self_collide>
  </gazebo>
  <gazebo reference="gripper_static_1">
    <material>Gazebo/Silver</material>
    <mu1>0.2</mu1>
    <mu2>0.2</mu2>
    <self_collide>true</self_collide>
  </gazebo>
  <gazebo reference="gripper_moving_1">
    <material>Gazebo/Silver</material>
    <mu1>0.2</mu1>
    <mu2>0.2</mu2>
    <self_collide>true</self_collide>
  </gazebo>
  <link name="base_link">
    <inertial>
      <origin rpy="0 0 0" xyz="-0.00017023202404845418 -0.021341439639662032 0.014423161616418092"/>
      <mass value="0.5164575020815119"/>
      <inertia ixx="0.000304" ixy="-2e-06" ixz="-1e-06" iyy="0.000283" iyz="-6.2e-05" izz="0.000441"/>
    </inertial>
    <visual>
      <origin rpy="0 0 0" xyz="0 0 0"/>
      <geometry>
        <mesh filename="file://$(find low_cost_robot_description)/meshes/base_link.stl" scale="0.001 0.001 0.001"/>
      </geometry>
      <material name="silver"/>
    </visual>
    <collision>
      <origin rpy="0 0 0" xyz="0 0 0"/>
      <geometry>
        <mesh filename="file://$(find low_cost_robot_description)/meshes/base_link.stl" scale="0.001 0.001 0.001"/>
      </geometry>
    </collision>
  </link>
  <link name="link1_1">
    <inertial>
      <origin rpy="0 0 0" xyz="-0.0006216635769899589 -0.011914175885676576 0.015400174574576098"/>
      <mass value="0.3956063453928257"/>
      <inertia ixx="0.000112" ixy="0.0" ixz="0.0" iyy="7.5e-05" iyz="-1e-06" izz="0.000123"/>
    </inertial>
    <visual>
      <origin rpy="0 0 0" xyz="-0.0 -0.0 -0.039"/>
      <geometry>
        <mesh filename="file://$(find low_cost_robot_description)/meshes/link1_1.stl" scale="0.001 0.001 0.001"/>
      </geometry>
      <material name="silver"/>
    </visual>
    <collision>
      <origin rpy="0 0 0" xyz="-0.0 -0.0 -0.039"/>
      <geometry>
        <mesh filename="file://$(find low_cost_robot_description)/meshes/link1_1.stl" scale="0.001 0.001 0.001"/>
      </geometry>
    </collision>
  </link>
  <link name="link2_1">
    <inertial>
      <origin rpy="0 0 0" xyz="0.00015778948024297947 -0.0012168309893684582 0.07161179945761596"/>
      <mass value="0.3916070272991037"/>
      <inertia ixx="0.00052" ixy="-1e-06" ixz="-2e-06" iyy="0.000534" iyz="-3.7e-05" izz="8.4e-05"/>
    </inertial>
    <visual>
      <origin rpy="0 0 0" xyz="0.0002 0.0 -0.0563"/>
      <geometry>
        <mesh filename="file://$(find low_cost_robot_description)/meshes/link2_1.stl" scale="0.001 0.001 0.001"/>
      </geometry>
      <material name="silver"/>
    </visual>
    <collision>
      <origin rpy="0 0 0" xyz="0.0002 0.0 -0.0563"/>
      <geometry>
        <mesh filename="file://$(find low_cost_robot_description)/meshes/link2_1.stl" scale="0.001 0.001 0.001"/>
      </geometry>
    </collision>
  </link>
  <link name="link3_1">
    <inertial>
      <origin rpy="0 0 0" xyz="7.243666489899892e-05 0.05069893196527342 0.002850799344132765"/>
      <mass value="0.4404689720232285"/>
      <inertia ixx="0.000302" ixy="-1e-06" ixz="0.0" iyy="5.5e-05" iyz="-0.0" izz="0.000322"/>
    </inertial>
    <visual>
      <origin rpy="0 0 0" xyz="-5e-05 -0.014791 -0.164647"/>
      <geometry>
        <mesh filename="file://$(find low_cost_robot_description)/meshes/link3_1.stl" scale="0.001 0.001 0.001"/>
      </geometry>
      <material name="silver"/>
    </visual>
    <collision>
      <origin rpy="0 0 0" xyz="-5e-05 -0.014791 -0.164647"/>
      <geometry>
        <mesh filename="file://$(find low_cost_robot_description)/meshes/link3_1.stl" scale="0.001 0.001 0.001"/>
      </geometry>
    </collision>
  </link>
  <link name="link4_1">
    <inertial>
      <origin rpy="0 0 0" xyz="-0.00473855751324301 8.608301182447264e-06 -0.02657822907239915"/>
      <mass value="0.15464443104629289"/>
      <inertia ixx="2.4e-05" ixy="0.0" ixz="-3e-06" iyy="3.9e-05" iyz="0.0" izz="2.4e-05"/>
    </inertial>
    <visual>
      <origin rpy="0 0 0" xyz="-0.000175 -0.105258 -0.167394"/>
      <geometry>
        <mesh filename="file://$(find low_cost_robot_description)/meshes/link4_1.stl" scale="0.001 0.001 0.001"/>
      </geometry>
      <material name="silver"/>
    </visual>
    <collision>
      <origin rpy="0 0 0" xyz="-0.000175 -0.105258 -0.167394"/>
      <geometry>
        <mesh filename="file://$(find low_cost_robot_description)/meshes/link4_1.stl" scale="0.001 0.001 0.001"/>
      </geometry>
    </collision>
  </link>
  <link name="gripper_static_1">
    <inertial>
      <origin rpy="0 0 0" xyz="0.005441113698877747 0.00011563276687967528 -0.019052234932530082"/>
      <mass value="0.23008611256824127"/>
      <inertia ixx="6.9e-05" ixy="-0.0" ixz="1.8e-05" iyy="8.4e-05" iyz="0.0" izz="4.3e-05"/>
    </inertial>
    <visual>
      <origin rpy="0 0 0" xyz="-0.001528 -0.105265 -0.122394"/>
      <geometry>
        <mesh filename="file://$(find low_cost_robot_description)/meshes/gripper_static_1.stl" scale="0.001 0.001 0.001"/>
      </geometry>
      <material name="silver"/>
    </visual>
    <collision>
      <origin rpy="0 0 0" xyz="-0.001528 -0.105265 -0.122394"/>
      <geometry>
        <mesh filename="file://$(find low_cost_robot_description)/meshes/gripper_static_1.stl" scale="0.001 0.001 0.001"/>
      </geometry>
    </collision>
  </link>
  <link name="gripper_moving_1">
    <inertial>
      <origin rpy="0 0 0" xyz="0.0010956016218150169 0.00031090398683926435 -0.02511314835420593"/>
      <mass value="0.10060550172576842"/>
      <inertia ixx="2.7e-05" ixy="-0.0" ixz="2e-06" iyy="1.9e-05" iyz="0.0" izz="1.2e-05"/>
    </inertial>
    <visual>
      <origin rpy="0 0 0" xyz="0.005872 -0.105015 -0.109244"/>
      <geometry>
        <mesh filename="file://$(find low_cost_robot_description)/meshes/gripper_moving_1.stl" scale="0.001 0.001 0.001"/>
      </geometry>
      <material name="silver"/>
    </visual>
    <collision>
      <origin rpy="0 0 0" xyz="0.005872 -0.105015 -0.109244"/>
      <geometry>
        <mesh filename="file://$(find low_cost_robot_description)/meshes/gripper_moving_1.stl" scale="0.001 0.001 0.001"/>
      </geometry>
    </collision>
  </link>
  <joint name="joint1" type="continuous">
    <origin rpy="0 0 0" xyz="0.0 0.0 0.039"/>
    <parent link="base_link"/>
    <child link="link1_1"/>
    <axis xyz="0.0 0.0 1.0"/>
  </joint>
  <joint name="joint2" type="continuous">
    <origin rpy="0 0 0" xyz="-0.0002 -0.0 0.0173"/>
    <parent link="link1_1"/>
    <child link="link2_1"/>
    <axis xyz="-1.0 -0.0 0.0"/>
  </joint>
  <joint name="joint3" type="continuous">
    <origin rpy="0 0 0" xyz="0.00025 0.014791 0.108347"/>
    <parent link="link2_1"/>
    <child link="link3_1"/>
    <axis xyz="1.0 0.0 0.0"/>
  </joint>
  <joint name="joint4" type="continuous">
    <origin rpy="0 0 0" xyz="0.000125 0.090467 0.002747"/>
    <parent link="link3_1"/>
    <child link="link4_1"/>
    <axis xyz="1.0 0.0 0.0"/>
  </joint>
  <joint name="joint5" type="continuous">
    <origin rpy="0 0 0" xyz="0.001353 7e-06 -0.045"/>
    <parent link="link4_1"/>
    <child link="gripper_static_1"/>
    <axis xyz="0.0 0.0 -1.0"/>
  </joint>
  <joint name="joint_gripper" type="continuous">
    <origin rpy="0 0 0" xyz="-0.0074 -0.00025 -0.01315"/>
    <parent link="gripper_static_1"/>
    <child link="gripper_moving_1"/>
    <axis xyz="-0.0 -1.0 -0.0"/>
  </joint>
</robot>
